<mujoco model="finger">
  <compiler angle="radian"/>
  <option gravity="0 0 -9.81" timestep="0.002"/>

  <asset>
    <mesh name="base_link" content_type="model/stl" file="../meshes/base_link.STL"/>
    <mesh name="splay_link" content_type="model/stl" file="../meshes/splay_link.STL"/>
    <mesh name="mcp_link" content_type="model/stl" file="../meshes/mcp_link.STL"/>
    <mesh name="pip_link" content_type="model/stl" file="../meshes/pip_link.STL"/>
  </asset>

  <worldbody>
    <geom name="floor" type="plane" size="1 1 0.1" rgba="0.8 0.8 0.8 1"/>

    <body name="base_link" pos="0 0 0.05">
      <inertial pos="0 0 0" mass="0.1" diaginertia="1e-4 1e-4 1e-4"/>
      <geom type="mesh" rgba="1 0 0 1" mesh="base_link"/>

      <body name="splay_link" pos="0.01504 0.018 0.012">
        <inertial pos="-0.001473 0.0073151 0.012091" quat="0.462705 -0.217849 0.235483 0.826434" mass="0.015542" diaginertia="1.4154e-06 1.4041e-06 1.23751e-06"/>
        <joint name="splay_joint" pos="0 0 0" axis="0 0 -1" range="-0.35 0.35" damping="0.05" stiffness="0.01"/>
        <geom type="mesh" rgba="0 0 0.8 1" mesh="splay_link"/>

        <body name="mcp_link" pos="0.005638 -0.077582 0.1311">
          <inertial pos="-0.015059 0.12618 -0.12292" quat="0.462246 0.51364 -0.440149 0.573386" mass="0.02221" diaginertia="3.60441e-06 2.80896e-06 2.36963e-06"/>
          <joint name="mcp_joint" pos="0 0 0" axis="0.982261 0.18752 0" range="-1.57 1.57" damping="0.05" stiffness="0.01"/>
          <geom type="mesh" rgba="1 1 0 1" mesh="mcp_link"/>

          <body name="pip_link" pos="-0.0080566 0.042211 0.0015151">
            <inertial pos="-0.015843 0.13082 -0.13497" quat="0.593854 0.280328 -0.235661 0.716392" mass="0.026547" diaginertia="5.11111e-06 4.55246e-06 3.12763e-06"/>
            <joint name="pip_joint" pos="0 0 0" axis="-0.982261 -0.18752 0" range="-1.57 1.57" damping="0.05" stiffness="0.01"/>
            <geom type="mesh" rgba="0 0.8 0 1" mesh="pip_link"/>
          </body>        <!-- closes pip_link -->

        </body>          <!-- closes mcp_link -->
      </body>            <!-- closes splay_link -->
    </body>              <!-- closes base_link -->
  </worldbody>
</mujoco>