<?xml version="1.0" encoding="utf-8"?>
<!-- This URDF was automatically created by SolidWorks to URDF Exporter! Originally created by Stephen Brawner (brawner@gmail.com) 
     Commit Version: 1.6.0-4-g7f85cfe  Build Version: 1.6.7995.38578
     For more information, please see http://wiki.ros.org/sw_urdf_exporter -->
<robot
  name="Full assembly_visual_urdf_export">
  <link
    name="base_link">
    <inertial>
      <origin
        xyz="0.014963 0.0095373 0.016002"
        rpy="0 0 0" />
      <mass
        value="0.011071" />
      <inertia
        ixx="2.4908E-06"
        ixy="-4.4596E-09"
        ixz="1.5947E-07"
        iyy="2.8376E-06"
        iyz="1.5412E-10"
        izz="2.3239E-06" />
    </inertial>
    <visual>
      <origin
        xyz="0 0 0"
        rpy="0 0 0" />
      <geometry>
        <mesh
          filename="package://Full assembly_visual_urdf_export/meshes/base_link.STL" />
      </geometry>
      <material
        name="">
        <color
          rgba="0.79216 0.81961 0.93333 1" />
      </material>
    </visual>
    <collision>
      <origin
        xyz="0 0 0"
        rpy="0 0 0" />
      <geometry>
        <mesh
          filename="package://Full assembly_visual_urdf_export/meshes/base_link.STL" />
      </geometry>
    </collision>
  </link>
  <link
    name="splay_link">
    <inertial>
      <origin
        xyz="-0.001473 0.0073151 0.012091"
        rpy="0 0 0" />
      <mass
        value="0.015542" />
      <inertia
        ixx="1.4033E-06"
        ixy="1.0423E-08"
        ixz="2.1923E-08"
        iyy="1.3509E-06"
        iyz="-8.2493E-08"
        izz="1.3028E-06" />
    </inertial>
    <visual>
      <origin
        xyz="0 0 0"
        rpy="0 0 0" />
      <geometry>
        <mesh
          filename="package://Full assembly_visual_urdf_export/meshes/splay_link.STL" />
      </geometry>
      <material
        name="">
        <color
          rgba="0.75294 0.75294 0.75294 1" />
      </material>
    </visual>
    <collision>
      <origin
        xyz="0 0 0"
        rpy="0 0 0" />
      <geometry>
        <mesh
          filename="package://Full assembly_visual_urdf_export/meshes/splay_link.STL" />
      </geometry>
    </collision>
  </link>
  <joint
    name="splay_joint"
    type="revolute">
    <origin
      xyz="0.01504 0.018 0.012"
      rpy="0 0 0" />
    <parent
      link="base_link" />
    <child
      link="splay_link" />
    <axis
      xyz="0 0 -1" />
    <limit
      lower="-0.35"
      upper="0.35"
      effort="0"
      velocity="0" />
  </joint>
  <link
    name="mcp_link">
    <inertial>
      <origin
        xyz="-0.015059 0.12618 -0.12292"
        rpy="0 0 0" />
      <mass
        value="0.02221" />
      <inertia
        ixx="2.796E-06"
        ixy="7.5586E-08"
        ixz="-4.2446E-08"
        iyy="2.3922E-06"
        iyz="9.8274E-08"
        izz="3.5948E-06" />
    </inertial>
    <visual>
      <origin
        xyz="0 0 0"
        rpy="0 0 0" />
      <geometry>
        <mesh
          filename="package://Full assembly_visual_urdf_export/meshes/mcp_link.STL" />
      </geometry>
      <material
        name="">
        <color
          rgba="0.75294 0.75294 0.75294 1" />
      </material>
    </visual>
    <collision>
      <origin
        xyz="0 0 0"
        rpy="0 0 0" />
      <geometry>
        <mesh
          filename="package://Full assembly_visual_urdf_export/meshes/mcp_link.STL" />
      </geometry>
    </collision>
  </link>
  <joint
    name="mcp_joint"
    type="revolute">
    <origin
      xyz="0.005638 -0.077582 0.1311"
      rpy="0 0 0" />
    <parent
      link="splay_link" />
    <child
      link="mcp_link" />
    <axis
      xyz="0.98226 0.18752 0" />
    <limit
      lower="0"
      upper="0"
      effort="0"
      velocity="0" />
  </joint>
  <link
    name="pip_link">
    <inertial>
      <origin
        xyz="-0.015843 0.13082 -0.13497"
        rpy="0 0 0" />
      <mass
        value="0.026547" />
      <inertia
        ixx="4.5419E-06"
        ixy="6.1121E-08"
        ixz="-1.793E-07"
        iyy="4.2003E-06"
        iyz="9.7285E-07"
        izz="4.049E-06" />
    </inertial>
    <visual>
      <origin
        xyz="0 0 0"
        rpy="0 0 0" />
      <geometry>
        <mesh
          filename="package://Full assembly_visual_urdf_export/meshes/pip_link.STL" />
      </geometry>
      <material
        name="">
        <color
          rgba="0.75294 0.75294 0.75294 1" />
      </material>
    </visual>
    <collision>
      <origin
        xyz="0 0 0"
        rpy="0 0 0" />
      <geometry>
        <mesh
          filename="package://Full assembly_visual_urdf_export/meshes/pip_link.STL" />
      </geometry>
    </collision>
  </link>
  <joint
    name="pip_joint"
    type="revolute">
    <origin
      xyz="-0.0080566 0.042211 0.0015151"
      rpy="0 0 0" />
    <parent
      link="mcp_link" />
    <child
      link="pip_link" />
    <axis
      xyz="-0.98226 -0.18752 0" />
    <limit
      lower="0"
      upper="0"
      effort="0"
      velocity="0" />
  </joint>
</robot>